<?xml version="1.0"?>
<robot name= "GoPiGo3">
    <link name="base_link">
        <visual>
            <geometry>
                <cylinder radius="0.075" length="0.01"/>                
            </geometry>
            <origin rpy="0.0 0.0 0.0" xyz="0.0 0.0 0.0375"/>
            <material name="red">
                <color rgba="1 0 0 1" />
            </material>
        </visual>
        <collision>
            <geometry>
                <cylinder radius="0.075" length="0.01"/>                
            </geometry>
                <origin rpy="0.0 0.0 0.0" xyz="0.0 0.0 0.0375"/>            
        </collision>
        <inertial>
            <mass value="1.0"/>
            <inertia ixx="1.0" ixy="0.0" ixz="0.0" iyy="1.0" iyz="0.0" izz="1.0"/>
        </inertial>
    </link>
    <joint name="right_wheel_to_base_link" type="revolute">
        <parent link="base_link"/>
        <child  link="right_wheel"/>
        <origin xyz="0.0 0.085 0.0375" rpy="0.0 0.0 0.0"/>
        <axis xyz="1.0 0.0 0.0"/>
        <limit lower="0.0" upper="6.28" effort="300" velocity="1"/>
    </joint>
    <link name="right_wheel">
        <visual>         
            <geometry>
                <cylinder radius="0.0375" length="0.02"/>
            </geometry>
             <material name="black">
                 <color rgba="1 1 0 1" />
            </material>
            <origin rpy="1.57075 0.0 0.0" xyz="0.0 0.0 0.0"/>
        </visual>
        <collision>
            <geometry>
                <cylinder radius="0.0375" length="0.02"/>
            </geometry>
            <origin rpy="1.57075 0.0 0.0" xyz="0.0 0.0 0.0"/>
        </collision>
        <inertial>
            <mass value="1.0"/>
            <inertia ixx="1.0" ixy="0.0" ixz="0.0" iyy="1.0" iyz="0.0" izz="1.0"/>
        </inertial>
    </link>
    <joint name="left_wheel_to_base_link" type="revolute">
        <parent link="base_link"/>
        <child  link="left_wheel"/>
        <origin xyz=" 0.0 -0.085 0.0375" rpy="0.0 0.0 0.0"/>
        <axis xyz="1.0 0.0 0.0"/>
        <limit lower="0.0" upper="6.28" effort="300" velocity="1"/>
    </joint>
    <link name="left_wheel">
        <visual>         
            <geometry>
                <cylinder radius="0.0375" length="0.02"/>
            </geometry>
             <material name="black">
                 <color rgba="1 1 0 1" />
            </material>
            <origin rpy="1.57075 0.0 0.0" xyz="0.0 0.0 0.0"/>
        </visual>
        <collision>
            <geometry>
                <cylinder radius="0.0375" length="0.02"/>
            </geometry>
            <origin rpy="1.5707 0.0 0.0" xyz="0.0 0.0 0.0"/>
        </collision>
        <inertial>
            <mass value="1.0"/>
            <inertia ixx="1.0" ixy="0.0" ixz="0.0" iyy="1.0" iyz="0.0" izz="1.0"/>
        </inertial>    
    </link>
    <joint name="counter_weight_to_base_link" type="fixed">
        <parent link="base_link"/>
        <child  link="counter_weight"/>
        <origin xyz="-0.03 0.0 0.02"/>
        <axis xyz="1.0 0.0 0.0"/>
    </joint>
    <link name="counter_weight">
        <visual>         
            <geometry>
                <sphere radius="0.0175"/>
            </geometry>
            <origin rpy="0.0 0 0.0" xyz="0.0 0.0 0.0"/> 
            <material name="red">
                 <color rgba="1 0 0 1" />
            </material>
        </visual>
        <collision>
            <geometry>
                <sphere radius="0.0175"/>
            </geometry>
            <origin rpy="0.0 0 0.0" xyz="0.0 0.0 0.0"/> 
        </collision>
        <inertial>
            <mass value="0.5"/>
            <inertia ixx="1.0" ixy="0.0" ixz="0.0" iyy="1.0" iyz="0.0" izz="1.0"/>
        </inertial>
    </link>
    <joint name="camera_link_to_base_link" type="revolute">
        <parent link="base_link"/>
        <child  link="camera_link"/>
        <origin xyz="0.075 0.0 0.065" rpy="-1.57075 0.0 -1.57075"/>
        <axis xyz="0.0 1.0 0.0"/>
        <limit lower="-0.5235" upper="0.5235" effort="300" velocity="1"/>
    </joint>
    <link name="camera_link">
        <visual>         
            <geometry>
                <box size="0.04 0.065 0.01"/>
            </geometry>
            <origin rpy="0.0 0.0 0.0" xyz="0.0 0.0 0.0"/>
             <material name="red">
                 <color rgba="1 0 0 1" />
            </material>
        </visual>
        <collision>
            <geometry>
                <box size="0.04 0.065 0.01"/>
            </geometry>
            <origin rpy="0.0 0.0 0.0" xyz="0.0 0.0 0.0"/>            
        </collision>
        <inertial>
            <mass value="0.15"/>
            <inertia ixx="1.0" ixy="0.0" ixz="0.0" iyy="1.0" iyz="0.0" izz="1.0"/>
        </inertial>
    </link>
</robot>
