<?xml version="1.0" encoding="utf-8"?>
<!-- =================================================================================== -->
<!-- |    This document was autogenerated by xacro from gpg.xacro                      | -->
<!-- |    EDITING THIS FILE BY HAND IS NOT RECOMMENDED                                 | -->
<!-- =================================================================================== -->
<robot name="GoPiGo3">
  <material name="red">
    <color rgba="1.0 0.0 0.0 1.0"/>
  </material>
  <material name="yellow">
    <color rgba="1.0 1.0 0.0 1.0"/>
  </material>
  <link name="base_link">
    <visual>
      <geometry>
        <cylinder length="0.01" radius="0.075"/>
      </geometry>
      <origin rpy="0.0 0.0 0.0" xyz="0.0 0.0 0.0375"/>
      <material name="red"/>
    </visual>
    <collision>
      <geometry>
        <cylinder length="0.01" radius="0.075"/>
      </geometry>
      <origin rpy="0.0 0.0 0.0" xyz="0.0 0.0 0.0375"/>
    </collision>
    <inertial>
      <mass value="1.0"/>
      <inertia ixx="1.0" ixy="0.0" ixz="0.0" iyy="1.0" iyz="0.0" izz="1.0"/>
    </inertial>
  </link>
  <joint name="right_wheel_to_base_link" type="revolute">
    <parent link="base_link"/>
    <child link="right_wheel"/>
    <origin rpy="0.0 0.0 3.1415" xyz="0.085 0.0 0.0375"/>
    <axis xyz="1.0 0.0 0.0"/>
    <limit effort="300" lower="0.0" upper="6.283" velocity="1.0"/>
  </joint>
  <link name="right_wheel">
    <visual>
      <geometry>
        <cylinder length="0.02" radius="0.0375"/>
      </geometry>
      <material name="yellow"/>
      <origin rpy="0.0 1.57075 0.0" xyz="0.0 0.0 0.0"/>
    </visual>
    <collision>
      <geometry>
        <cylinder length="0.02" radius="0.0375"/>
      </geometry>
      <origin rpy="0.0 1.57075 0.0" xyz="0.0 0.0 0.0"/>
    </collision>
    <inertial>
      <mass value="1.0"/>
      <inertia ixx="1.0" ixy="0.0" ixz="0.0" iyy="1.0" iyz="0.0" izz="1.0"/>
    </inertial>
  </link>
  <joint name="left_wheel_to_base_link" type="revolute">
    <parent link="base_link"/>
    <child link="left_wheel"/>
    <origin rpy="0.0 0.0 3.1415" xyz="-0.085 0.0 0.0375"/>
    <axis xyz="1.0 0.0 0.0"/>
    <limit effort="300" lower="0.0" upper="6.283" velocity="1.0"/>
  </joint>
  <link name="left_wheel">
    <visual>
      <geometry>
        <cylinder length="0.02" radius="0.0375"/>
      </geometry>
      <material name="yellow"/>
      <origin rpy="0.0 1.57075 0.0" xyz="0.0 0.0 0.0"/>
    </visual>
    <collision>
      <geometry>
        <cylinder length="0.02" radius="0.0375"/>
      </geometry>
      <origin rpy="0.0 1.57075 0.0" xyz="0.0 0.0 0.0"/>
    </collision>
    <inertial>
      <mass value="1.0"/>
      <inertia ixx="1.0" ixy="0.0" ixz="0.0" iyy="1.0" iyz="0.0" izz="1.0"/>
    </inertial>
  </link>
  <joint name="counter_weight_to_base_link" type="fixed">
    <parent link="base_link"/>
    <child link="counter_weight"/>
    <origin xyz="0.0 -0.0375 0.015"/>
    <axis xyz="1.0 0.0 0.0"/>
  </joint>
  <link name="counter_weight">
    <visual>
      <geometry>
        <sphere radius="0.0175"/>
      </geometry>
      <origin rpy="0.0 0 0.0" xyz="0.0 0.0 0.0"/>
      <material name="red"/>
    </visual>
    <collision>
      <geometry>
        <sphere radius="0.0175"/>
      </geometry>
      <origin rpy="0.0 0 0.0" xyz="0.0 0.0 0.0"/>
    </collision>
    <inertial>
      <mass value="0.5"/>
      <inertia ixx="1.0" ixy="0.0" ixz="0.0" iyy="1.0" iyz="0.0" izz="1.0"/>
    </inertial>
  </link>
  <joint name="camera_link_to_base_link" type="revolute">
    <parent link="base_link"/>
    <child link="camera_link"/>
    <origin rpy="-1.57075 0.0 0.0" xyz="0.0 0.075 0.065"/>
    <axis xyz="0.0 1.0 0.0"/>
    <limit effort="300" lower="-0.0" upper="0.0" velocity="1.0"/>
  </joint>
  <link name="camera_link">
    <visual>
      <geometry>
        <box size="0.04 0.065 0.01"/>
      </geometry>
      <origin rpy="0.0 0.0 0.0" xyz="0.0 0.0 0.0"/>
      <material name="red"/>
    </visual>
    <collision>
      <geometry>
        <box size="0.04 0.065 0.01"/>
      </geometry>
      <origin rpy="0.0 0.0 0.0" xyz="0.0 0.0 0.0"/>
    </collision>
    <inertial>
      <mass value="0.15"/>
      <inertia ixx="1.0" ixy="0.0" ixz="0.0" iyy="1.0" iyz="0.0" izz="1.0"/>
    </inertial>
  </link>
</robot>
