<?xml version="1.0"?>
<robot name="gopigo">

  <material name="blue">
    <color rgba="0 0 0.8 1"/>
  </material>
  <material name="black">
    <color rgba="0 0 0 1"/>
  </material>
  <material name="white">
    <color rgba="1 1 1 1"/>
  </material>

  <link name="base_link">
    <visual>
      <geometry>
        <cylinder length="0.01" radius="0.075"/>
      </geometry>
      <material name="white"/>
    </visual>
    <collision>
      <geometry>
        <cylinder length="0.01" radius="0.075"/>
      </geometry>
    </collision>


  </link>
  
  <link name="right_wheel_link">
    <visual>
      <geometry>
        <cylinder length="0.015" radius="0.035"/>
      </geometry>
      <origin rpy="1.57075 0 0" xyz="0 0 0"/>
      <material name="black"/>
    </visual>
    <collision>
      <geometry>
        <cylinder length="0.015" radius="0.035"/>
      </geometry>
      <origin rpy="1.57075 0 0" xyz="0 0 0"/>
    </collision>
    <inertial>
            <mass value="0.15" />
            <origin xyz="0 0 0" rpy="0 0 0" />
            <inertia ixx="0.001" ixy="0.0" ixz="0" iyy="0.001" iyz="0" izz="0.001" />
    </inertial>
  </link>
  
  <joint name="right_wheel" type="continuous">
    <parent link="base_link"/>
    <child link="right_wheel_link"/>
    <axis xyz="0 1 0"/>
    <origin xyz="0 -0.075 0"/>
  </joint>
  
  <link name="left_wheel_link">
    <visual>
      <geometry>
        <cylinder length="0.015" radius="0.035"/>
      </geometry>
      <origin rpy="1.57075 0 0" xyz="0 0 0"/>
      <material name="black"/>
    </visual>
    <collision>
      <geometry>
        <cylinder length="0.015" radius="0.035"/>
      </geometry>
      <origin rpy="1.57075 0 0" xyz="0 0 0"/>
    </collision>
    <inertial>
            <mass value="0.15" />
            <origin xyz="0 0 0" rpy="0 0 0" />
            <inertia ixx="0.001" ixy="0.0" ixz="0" iyy="0.001" iyz="0" izz="0.001" />
    </inertial>
  </link>
  
  <joint name="left_wheel" type="continuous">
    <parent link="base_link"/>
    <child link="left_wheel_link"/>
    <axis xyz="0 1 0"/>
    <origin xyz="0 0.075 0"/>
  </joint>
  
  <link name="camera_link">
    <visual>
      <geometry>
        <box size="0.03 0.06 0.005"/>
      </geometry>
      <origin rpy="0 0 0" xyz="0 0.005 0"/>
      <material name="blue"/>
    </visual>
    <collision>
      <geometry>
        <box size="0.03 0.06 0.005"/>
      </geometry>
      <origin rpy="0 0 0" xyz="0 0.005 0"/>
    </collision>
    <inertial>
            <mass value="0.1" />
            <origin xyz="0 0 0" rpy="0 0 0" />
            <inertia ixx="0.001" ixy="0.0" ixz="0" iyy="0.001" iyz="0" izz="0.001" />
    </inertial>
  </link>
  
  <joint name="servo" type="revolute">
    <axis xyz="0 -1 0"/>
    <limit effort="1000.0" lower="-1.57075" upper="1.57075" velocity="0.5"/>
    <parent link="base_link"/>
    <child link="camera_link"/>
    <origin rpy="1.57075 3.1415 1.57075" xyz="0.075 0 0.03"/>
  </joint>
  
  <link name="weight_link">
    <visual>
      <geometry>
        <sphere radius="0.0125"/>
      </geometry>
      <origin rpy="0 0 0" xyz="0 0 0"/>
      <material name="blue"/>
    </visual>
    <collision>
      <geometry>
        <sphere radius="0.0125"/>
      </geometry>
      <origin rpy="0 0 0" xyz="0 0 0"/>
    </collision>
    <inertial>
            <mass value="0.3" />
            <origin xyz="0 0 0" rpy="0 0 0" />
            <inertia ixx="0.001" ixy="0.0" ixz="0" iyy="0.001" iyz="0" izz="0.001" />
    </inertial>
  </link>
  
  <joint name="weight" type="fixed">
    <parent link="base_link"/>
    <child link="weight_link"/>
    <origin rpy="0 0 0" xyz="-0.06 0 -0.015"/>
  </joint>
  
  <!-- Transmission-->
  <transmission name="servo_trans">
    <type>transmission_interface/SimpleTransmission</type>
    <actuator name="$servo_motor">
      <mechanicalReduction>1</mechanicalReduction>
    </actuator>
    <joint name="servo">
      <hardwareInterface>hardware_interface/PositionJointInterface</hardwareInterface>
    </joint>
  </transmission>
  
  <transmission name="rwheel_trans">
    <type>transmission_interface/SimpleTransmission</type>
    <actuator name="$rwheel_motor">
      <mechanicalReduction>1</mechanicalReduction>
    </actuator>
    <joint name="right_wheel">
      <hardwareInterface>hardware_interface/VelocityJointInterface</hardwareInterface>
    </joint>
  </transmission>
  
  <transmission name="lwheel_trans">
    <type>transmission_interface/SimpleTransmission</type>
    <actuator name="$lwheel_motor">
      <mechanicalReduction>1</mechanicalReduction>
    </actuator>
    <joint name="left_wheel">
      <hardwareInterface>hardware_interface/VelocityJointInterface</hardwareInterface>
    </joint>
  </transmission>
  
  <!-- Gazebo plugin-->
  <gazebo>
    <plugin name="gazebo_ros_control" filename="libgazebo_ros_control.so">
      <robotNamespace>/gpg</robotNamespace>
      <legacyModeNS>false</legacyModeNS>
    </plugin>
  </gazebo>
  <gazebo reference="base_line">
    <material>Gazebo/White</material>
  </gazebo>
  <gazebo reference="left_wheel_link">
    <material>Gazebo/Grey</material>
  </gazebo>
  <gazebo reference="right_wheel_link">
    <material>Gazebo/Grey</material>
  </gazebo>
  <gazebo reference="camera_link">
    <material>Gazebo/Blue</material>
  </gazebo>
  <gazebo reference="weight_link">
    <mu1>0</mu1>
    <mu2>0</mu2>
    <material>Gazebo/Blue</material>
  </gazebo>
  
    <!-- camera -->
  <gazebo reference="camera_link">
    <sensor type="camera" name="camera1">
      <update_rate>30.0</update_rate>
      <camera name="head">
        <pose >0 0 0 1.57075 -1.57075 0 </pose>
        <horizontal_fov>0.915</horizontal_fov>
        <image>
          <width>320</width>
          <height>240</height>
          <format>R8G8B8</format>
        </image>
        <clip>
          <near>0.02</near>
          <far>300</far>
        </clip>
        <noise>
          <type>gaussian</type>
          <!-- Noise is sampled independently per pixel on each frame.
               That pixel's noise value is added to each of its color
               channels, which at that point lie in the range [0,1]. -->
          <mean>0.0</mean>
          <stddev>0.007</stddev>
        </noise>
      </camera>
      <plugin name="camera_controller" filename="libgazebo_ros_camera.so">
        <alwaysOn>true</alwaysOn>
        <updateRate>30.0</updateRate>
        <cameraName>gpg</cameraName>
        <imageTopicName>image</imageTopicName>
        <cameraInfoTopicName>camera_info</cameraInfoTopicName>
        <frameName>camera_link</frameName>
        <hackBaseline>0.0</hackBaseline>
        <distortionK1>0.0809380</distortionK1>
        <distortionK2>-0.257429</distortionK2>
        <distortionK3>0.0</distortionK3>
        <distortionT1>-0.002955</distortionT1>
        <distortionT2>0.003629</distortionT2>
      </plugin>
    </sensor>
  </gazebo>  
</robot>
